Workbook
Name Slicer_City: #N/A
Name Slicer_Month: #N/A

Sheet Pivot
A3: Category | B3: Sum of Net Revenue | D3: City | E3: Sum of Net Revenue | G3: Month | H3: Sum of Net Revenue
A4: Electronics | B4: 179205.2 | D4: Bengaluru | E4: 62297.481 | G4: Apr-2026 | H4: 72152.268
A5: Fashion | B5: 74673.846 | D5: Bhubaneswar | E5: 40778.362 | G5: Feb-2026 | H5: 69670.656
A6: Food & Beverage | B6: 22663.751 | D6: Chennai | E6: 38687.255 | G6: Jan-2026 | H6: 40682.241
A7: Grocery | B7: 31986.249 | D7: Delhi | E7: 43207.195 | G7: Jun-2026 | H7: 54727.284
A8: Home & Living | B8: 56806.626 | D8: Hyderabad | E8: 47101.951 | G8: Mar-2026 | H8: 81661.369
A9: Pharmacy | B9: 17339.38 | D9: Kolkata | E9: 25854.54 | G9: May-2026 | H9: 63781.235
A10: Grand Total | B10: 382675.05 | D10: Mumbai | E10: 51737.585 | G10: Grand Total | H10: 382675.05
D11: Pune | E11: 73010.685
D12: Grand Total | E12: 382675.05
A15: Payment Method | B15: Sum of Net Revenue | D15: Month | E15: Total Profit | F15: Total Loss | H15: Delivery Status | I15: Sum of Net Revenue | J15: Count of Order ID
A16: Cash on Delivery | B16: 110397.12 | D16: Apr-2026 | E16: 14454.47 | F16: 1332.6186 | H16: Cancelled | I16: 0 | J16: 12
A17: Credit/Debit Card | B17: 98127.144 | D17: Feb-2026 | E17: 15949.249 | F17: 2522.8721 | H17: Delivered | I17: 382264.05 | J17: 192
A18: Net Banking | B18: 74884.815 | D18: Jan-2026 | E18: 10237.418 | F18: 4344.5773 | H18: Returned | I18: 411 | J18: 16
A19: UPI/Wallet | B19: 99265.979 | D19: Jun-2026 | E19: 10522.553 | F19: 14136.774 | H19: Grand Total | I19: 382675.05 | J19: 220
A20: Grand Total | B20: 382675.05 | D20: Mar-2026 | E20: 12522.484 | F20: 3182.2317
D21: May-2026 | E21: 13475.931 | F21: 9123.1602
D22: Grand Total | E22: 77162.105 | F22: 34642.234
A25: Sum of Net Revenue | B25: Sum of Net Profit | C25: Count of Orders | D25: Average of Delivery Time | E25: Average of Rating
A26: 382675.05 | B26: 42519.871 | C26: 220 | D26: 56.524038 | E26: 3.9038462
A50: Category | B50: Revenue | D50: City | E50: Revenue | G50: Month | H50: Revenue | J50: Payment Method | K50: Revenue | M50: Month | N50: Total Profit | O50: Total Loss
A51: =Pivot!$A$4 -> Electronics | B51: =Pivot!$B$4 -> 179205.2 | D51: =Pivot!$D$4 -> Bengaluru | E51: =Pivot!$E$4 -> 62297.481 | G51: =Pivot!$G$4 -> Apr-2026 | H51: =Pivot!$H$4 -> 72152.268 | J51: =Pivot!$A$16 -> Cash on Delivery | K51: =Pivot!$B$16 -> 110397.12 | M51: =Pivot!$D$16 -> Apr-2026 | N51: =Pivot!$E$16 -> 14454.47 | O51: =Pivot!$F$16 -> 1332.6186
A52: =Pivot!$A$5 -> Fashion | B52: =Pivot!$B$5 -> 74673.846 | D52: =Pivot!$D$5 -> Bhubaneswar | E52: =Pivot!$E$5 -> 40778.362 | G52: =Pivot!$G$5 -> Feb-2026 | H52: =Pivot!$H$5 -> 69670.656 | J52: =Pivot!$A$17 -> Credit/Debit Card | K52: =Pivot!$B$17 -> 98127.144 | M52: =Pivot!$D$17 -> Feb-2026 | N52: =Pivot!$E$17 -> 15949.249 | O52: =Pivot!$F$17 -> 2522.8721
A53: =Pivot!$A$6 -> Food & Beverage | B53: =Pivot!$B$6 -> 22663.751 | D53: =Pivot!$D$6 -> Chennai | E53: =Pivot!$E$6 -> 38687.255 | G53: =Pivot!$G$6 -> Jan-2026 | H53: =Pivot!$H$6 -> 40682.241 | J53: =Pivot!$A$18 -> Net Banking | K53: =Pivot!$B$18 -> 74884.815 | M53: =Pivot!$D$18 -> Jan-2026 | N53: =Pivot!$E$18 -> 10237.418 | O53: =Pivot!$F$18 -> 4344.5773
A54: =Pivot!$A$7 -> Grocery | B54: =Pivot!$B$7 -> 31986.249 | D54: =Pivot!$D$7 -> Delhi | E54: =Pivot!$E$7 -> 43207.195 | G54: =Pivot!$G$7 -> Jun-2026 | H54: =Pivot!$H$7 -> 54727.284 | J54: =Pivot!$A$19 -> UPI/Wallet | K54: =Pivot!$B$19 -> 99265.979 | M54: =Pivot!$D$19 -> Jun-2026 | N54: =Pivot!$E$19 -> 10522.553 | O54: =Pivot!$F$19 -> 14136.774
A55: =Pivot!$A$8 -> Home & Living | B55: =Pivot!$B$8 -> 56806.626 | D55: =Pivot!$D$8 -> Hyderabad | E55: =Pivot!$E$8 -> 47101.951 | G55: =Pivot!$G$8 -> Mar-2026 | H55: =Pivot!$H$8 -> 81661.369 | M55: =Pivot!$D$20 -> Mar-2026 | N55: =Pivot!$E$20 -> 12522.484 | O55: =Pivot!$F$20 -> 3182.2317
A56: =Pivot!$A$9 -> Pharmacy | B56: =Pivot!$B$9 -> 17339.38 | D56: =Pivot!$D$9 -> Kolkata | E56: =Pivot!$E$9 -> 25854.54 | G56: =Pivot!$G$9 -> May-2026 | H56: =Pivot!$H$9 -> 63781.235 | M56: =Pivot!$D$21 -> May-2026 | N56: =Pivot!$E$21 -> 13475.931 | O56: =Pivot!$F$21 -> 9123.1602
D57: =Pivot!$D$10 -> Mumbai | E57: =Pivot!$E$10 -> 51737.585
D58: =Pivot!$D$11 -> Pune | E58: =Pivot!$E$11 -> 73010.685

Sheet Riders (HR)
A1: Rider ID | B1: Name | C1: City | D1: Join Date | E1: Employment Status | F1: Monthly Base Pay ($) | G1: Total Orders Assigned | H1: Delivered Orders | I1: On-Time Deliveries (<=45 min) | J1: On-Time % | K1: Avg Customer Rating | L1: Avg Delivery Time (mins) | M1: Rank Key
A2: RD1001 | B2: Suresh Kumar | C2: Pune | D2: 45679 | E2: Active | F2: 16000 | G2: =COUNTIF(Orders!$M$2:$M$221,$B2) -> 6 | H2: =COUNTIFS(Orders!$M$2:$M$221,$B2,Orders!$N$2:$N$221,"Delivered") -> 6 | I2: =COUNTIFS(Orders!$M$2:$M$221,$B2,Orders!$N$2:$N$221,"Delivered",Orders!$O$2:$O$221,"<=45") -> 2 | J2: =IFERROR(I2/H2,0) -> 0.33333333 | K2: =IFERROR(AVERAGEIFS(Orders!$P$2:$P$221,Orders!$M$2:$M$221,$B2,Orders!$N$2:$N$221,"Delivered"),0) -> 4.3333333 | L2: =IFERROR(AVERAGEIFS(Orders!$O$2:$O$221,Orders!$M$2:$M$221,$B2,Orders!$N$2:$N$221,"Delivered"),0) -> 60.833333 | M2: =H2-ROW()/100000 -> 5.99998
A3: RD1002 | B3: Ramesh Yadav | C3: Hyderabad | D3: 45477 | E3: Active | F3: 14000 | G3: =COUNTIF(Orders!$M$2:$M$221,$B3) -> 14 | H3: =COUNTIFS(Orders!$M$2:$M$221,$B3,Orders!$N$2:$N$221,"Delivered") -> 13 | I3: =COUNTIFS(Orders!$M$2:$M$221,$B3,Orders!$N$2:$N$221,"Delivered",Orders!$O$2:$O$221,"<=45") -> 9 | J3: =IFERROR(I3/H3,0) -> 0.69230769 | K3: =IFERROR(AVERAGEIFS(Orders!$P$2:$P$221,Orders!$M$2:$M$221,$B3,Orders!$N$2:$N$221,"Delivered"),0) -> 4 | L3: =IFERROR(AVERAGEIFS(Orders!$O$2:$O$221,Orders!$M$2:$M$221,$B3,Orders!$N$2:$N$221,"Delivered"),0) -> 44.538462 | M3: =H3-ROW()/100000 -> 12.99997
A4: RD1003 | B4: Anita Behera | C4: Pune | D4: 45698 | E4: Active | F4: 14000 | G4: =COUNTIF(Orders!$M$2:$M$221,$B4) -> 5 | H4: =COUNTIFS(Orders!$M$2:$M$221,$B4,Orders!$N$2:$N$221,"Delivered") -> 5 | I4: =COUNTIFS(Orders!$M$2:$M$221,$B4,Orders!$N$2:$N$221,"Delivered",Orders!$O$2:$O$221,"<=45") -> 1 | J4: =IFERROR(I4/H4,0) -> 0.2 | K4: =IFERROR(AVERAGEIFS(Orders!$P$2:$P$221,Orders!$M$2:$M$221,$B4,Orders!$N$2:$N$221,"Delivered"),0) -> 4.2 | L4: =IFERROR(AVERAGEIFS(Orders!$O$2:$O$221,Orders!$M$2:$M$221,$B4,Orders!$N$2:$N$221,"Delivered"),0) -> 57 | M4: =H4-ROW()/100000 -> 4.99996
A5: RD1004 | B5: Bikash Mallick | C5: Pune | D5: 45367 | E5: Active | F5: 18000 | G5: =COUNTIF(Orders!$M$2:$M$221,$B5) -> 16 | H5: =COUNTIFS(Orders!$M$2:$M$221,$B5,Orders!$N$2:$N$221,"Delivered") -> 12 | I5: =COUNTIFS(Orders!$M$2:$M$221,$B5,Orders!$N$2:$N$221,"Delivered",Orders!$O$2:$O$221,"<=45") -> 8 | J5: =IFERROR(I5/H5,0) -> 0.66666667 | K5: =IFERROR(AVERAGEIFS(Orders!$P$2:$P$221,Orders!$M$2:$M$221,$B5,Orders!$N$2:$N$221,"Delivered"),0) -> 4.1666667 | L5: =IFERROR(AVERAGEIFS(Orders!$O$2:$O$221,Orders!$M$2:$M$221,$B5,Orders!$N$2:$N$221,"Delivered"),0) -> 45.416667 | M5: =H5-ROW()/100000 -> 11.99995
A6: RD1005 | B6: Deepak Sahu | C6: Bhubaneswar | D6: 45660 | E6: Active | F6: 18000 | G6: =COUNTIF(Orders!$M$2:$M$221,$B6) -> 10 | H6: =COUNTIFS(Orders!$M$2:$M$221,$B6,Orders!$N$2:$N$221,"Delivered") -> 10 | I6: =COUNTIFS(Orders!$M$2:$M$221,$B6,Orders!$N$2:$N$221,"Delivered",Orders!$O$2:$O$221,"<=45") -> 2 | J6: =IFERROR(I6/H6,0) -> 0.2 | K6: =IFERROR(AVERAGEIFS(Orders!$P$2:$P$221,Orders!$M$2:$M$221,$B6,Orders!$N$2:$N$221,"Delivered"),0) -> 3.8 | L6: =IFERROR(AVERAGEIFS(Orders!$O$2:$O$221,Orders!$M$2:$M$221,$B6,Orders!$N$2:$N$221,"Delivered"),0) -> 68.1 | M6: =H6-ROW()/100000 -> 9.99994
A7: RD1006 | B7: Farhan Ali | C7: Hyderabad | D7: 45566 | E7: Active | F7: 16000 | G7: =COUNTIF(Orders!$M$2:$M$221,$B7) -> 8 | H7: =COUNTIFS(Orders!$M$2:$M$221,$B7,Orders!$N$2:$N$221,"Delivered") -> 5 | I7: =COUNTIFS(Orders!$M$2:$M$221,$B7,Orders!$N$2:$N$221,"Delivered",Orders!$O$2:$O$221,"<=45") -> 2 | J7: =IFERROR(I7/H7,0) -> 0.4 | K7: =IFERROR(AVERAGEIFS(Orders!$P$2:$P$221,Orders!$M$2:$M$221,$B7,Orders!$N$2:$N$221,"Delivered"),0) -> 4.6 | L7: =IFERROR(AVERAGEIFS(Orders!$O$2:$O$221,Orders!$M$2:$M$221,$B7,Orders!$N$2:$N$221,"Delivered"),0) -> 50.8 | M7: =H7-ROW()/100000 -> 4.99993
A8: RD1007 | B8: Gaurav Nanda | C8: Bhubaneswar | D8: 45766 | E8: Active | F8: 15000 | G8: =COUNTIF(Orders!$M$2:$M$221,$B8) -> 9 | H8: =COUNTIFS(Orders!$M$2:$M$221,$B8,Orders!$N$2:$N$221,"Delivered") -> 6 | I8: =COUNTIFS(Orders!$M$2:$M$221,$B8,Orders!$N$2:$N$221,"Delivered",Orders!$O$2:$O$221,"<=45") -> 2 | J8: =IFERROR(I8/H8,0) -> 0.33333333 | K8: =IFERROR(AVERAGEIFS(Orders!$P$2:$P$221,Orders!$M$2:$M$221,$B8,Orders!$N$2:$N$221,"Delivered"),0) -> 4.3333333 | L8: =IFERROR(AVERAGEIFS(Orders!$O$2:$O$221,Orders!$M$2:$M$221,$B8,Orders!$N$2:$N$221,"Delivered"),0) -> 60.833333 | M8: =H8-ROW()/100000 -> 5.99992
A9: RD1008 | B9: Harpreet Singh | C9: Mumbai | D9: 45709 | E9: Active | F9: 15000 | G9: =COUNTIF(Orders!$M$2:$M$221,$B9) -> 14 | H9: =COUNTIFS(Orders!$M$2:$M$221,$B9,Orders!$N$2:$N$221,"Delivered") -> 13 | I9: =COUNTIFS(Orders!$M$2:$M$221,$B9,Orders!$N$2:$N$221,"Delivered",Orders!$O$2:$O$221,"<=45") -> 3 | J9: =IFERROR(I9/H9,0) -> 0.23076923 | K9: =IFERROR(AVERAGEIFS(Orders!$P$2:$P$221,Orders!$M$2:$M$221,$B9,Orders!$N$2:$N$221,"Delivered"),0) -> 3.8461538 | L9: =IFERROR(AVERAGEIFS(Orders!$O$2:$O$221,Orders!$M$2:$M$221,$B9,Orders!$N$2:$N$221,"Delivered"),0) -> 63.461538 | M9: =H9-ROW()/100000 -> 12.99991
A10: RD1009 | B10: Imran Khan | C10: Delhi | D10: 45462 | E10: Active | F10: 17000 | G10: =COUNTIF(Orders!$M$2:$M$221,$B10) -> 12 | H10: =COUNTIFS(Orders!$M$2:$M$221,$B10,Orders!$N$2:$N$221,"Delivered") -> 9 | I10: =COUNTIFS(Orders!$M$2:$M$221,$B10,Orders!$N$2:$N$221,"Delivered",Orders!$O$2:$O$221,"<=45") -> 3 | J10: =IFERROR(I10/H10,0) -> 0.33333333 | K10: =IFERROR(AVERAGEIFS(Orders!$P$2:$P$221,Orders!$M$2:$M$221,$B10,Orders!$N$2:$N$221,"Delivered"),0) -> 3.8888889 | L10: =IFERROR(AVERAGEIFS(Orders!$O$2:$O$221,Orders!$M$2:$M$221,$B10,Orders!$N$2:$N$221,"Delivered"),0) -> 53.222222 | M10: =H10-ROW()/100000 -> 8.9999
A11: RD1010 | B11: Jyoti Panda | C11: Delhi | D11: 45401 | E11: Active | F11: 18000 | G11: =COUNTIF(Orders!$M$2:$M$221,$B11) -> 18 | H11: =COUNTIFS(Orders!$M$2:$M$221,$B11,Orders!$N$2:$N$221,"Delivered") -> 16 | I11: =COUNTIFS(Orders!$M$2:$M$221,$B11,Orders!$N$2:$N$221,"Delivered",Orders!$O$2:$O$221,"<=45") -> 7 | J11: =IFERROR(I11/H11,0) -> 0.4375 | K11: =IFERROR(AVERAGEIFS(Orders!$P$2:$P$221,Orders!$M$2:$M$221,$B11,Orders!$N$2:$N$221,"Delivered"),0) -> 4.125 | L11: =IFERROR(AVERAGEIFS(Orders!$O$2:$O$221,Orders!$M$2:$M$221,$B11,Orders!$N$2:$N$221,"Delivered"),0) -> 52.0625 | M11: =H11-ROW()/100000 -> 15.99989
A12: RD1011 | B12: Kunal Mehta | C12: Bhubaneswar | D12: 45487 | E12: Active | F12: 18000 | G12: =COUNTIF(Orders!$M$2:$M$221,$B12) -> 15 | H12: =COUNTIFS(Orders!$M$2:$M$221,$B12,Orders!$N$2:$N$221,"Delivered") -> 13 | I12: =COUNTIFS(Orders!$M$2:$M$221,$B12,Orders!$N$2:$N$221,"Delivered",Orders!$O$2:$O$221,"<=45") -> 3 | J12: =IFERROR(I12/H12,0) -> 0.23076923 | K12: =IFERROR(AVERAGEIFS(Orders!$P$2:$P$221,Orders!$M$2:$M$221,$B12,Orders!$N$2:$N$221,"Delivered"),0) -> 3.9230769 | L12: =IFERROR(AVERAGEIFS(Orders!$O$2:$O$221,Orders!$M$2:$M$221,$B12,Orders!$N$2:$N$221,"Delivered"),0) -> 57.615385 | M12: =H12-ROW()/100000 -> 12.99988
A13: RD1012 | B13: Lalita Rout | C13: Mumbai | D13: 45415 | E13: Active | F13: 16000 | G13: =COUNTIF(Orders!$M$2:$M$221,$B13) -> 11 | H13: =COUNTIFS(Orders!$M$2:$M$221,$B13,Orders!$N$2:$N$221,"Delivered") -> 10 | I13: =COUNTIFS(Orders!$M$2:$M$221,$B13,Orders!$N$2:$N$221,"Delivered",Orders!$O$2:$O$221,"<=45") -> 1 | J13: =IFERROR(I13/H13,0) -> 0.1 | K13: =IFERROR(AVERAGEIFS(Orders!$P$2:$P$221,Orders!$M$2:$M$221,$B13,Orders!$N$2:$N$221,"Delivered"),0) -> 4.4 | L13: =IFERROR(AVERAGEIFS(Orders!$O$2:$O$221,Orders!$M$2:$M$221,$B13,Orders!$N$2:$N$221,"Delivered"),0) -> 66 | M13: =H13-ROW()/100000 -> 9.99987
... A21: RD1020 | B21: Usha Rani | C21: Hyderabad | D21: 45490 | E21: Active | F21: 14000 | G21: =COUNTIF(Orders!$M$2:$M$221,$B21) -> 7 | H21: =COUNTIFS(Orders!$M$2:$M$221,$B21,Orders!$N$2:$N$221,"Delivered") -> 7 | I21: =COUNTIFS(Orders!$M$2:$M$221,$B21,Orders!$N$2:$N$221,"Delivered",Orders!$O$2:$O$221,"<=45") -> 0 | J21: =IFERROR(I21/H21,0) -> 0 | K21: =IFERROR(AVERAGEIFS(Orders!$P$2:$P$221,Orders!$M$2:$M$221,$B21,Orders!$N$2:$N$221,"Delivered"),0) -> 3.8571429 | L21: =IFERROR(AVERAGEIFS(Orders!$O$2:$O$221,Orders!$M$2:$M$221,$B21,Orders!$N$2:$N$221,"Delivered"),0) -> 67.285714 | M21: =H21-ROW()/100000 -> 6.99979

Sheet Loss Analysis
B2: Loss Cause Analysis — supports the Dashboard's month-wise Profit/Loss table
B4: Loss Orders by Month and Cause
B5: Month | C5: Order Cancelled | D5: Order Returned | E5: High Discount | F5: Delivery Cost Exceeded Order Value | G5: Low Order Value / Thin Margin | H5: Total Loss Orders | I5: Most Common Cause | J5: Least Common Cause
B6: Jan-2026 | C6: =COUNTIFS(Orders!$Q$2:$Q$221,$B6,Orders!$Z$2:$Z$221,C$5) -> 3 | D6: =COUNTIFS(Orders!$Q$2:$Q$221,$B6,Orders!$Z$2:$Z$221,D$5) -> 3 | E6: =COUNTIFS(Orders!$Q$2:$Q$221,$B6,Orders!$Z$2:$Z$221,E$5) -> 1 | F6: =COUNTIFS(Orders!$Q$2:$Q$221,$B6,Orders!$Z$2:$Z$221,F$5) -> 0 | G6: =COUNTIFS(Orders!$Q$2:$Q$221,$B6,Orders!$Z$2:$Z$221,G$5) -> 0 | H6: =SUM(C6:G6) -> 7 | I6: =IF(H6=0,"No Losses",INDEX($C$5:$G$5,MATCH(MAX(C6:G6),C6:G6,0))) -> Order Cancelled | J6: =IF(H6=0,"No Losses",INDEX($C$5:$G$5,MATCH(MIN(N6:R6),N6:R6,0))) -> High Discount | N6: =IF(C6=0,99999,C6) -> 3 | O6: =IF(D6=0,99999,D6) -> 3 | P6: =IF(E6=0,99999,E6) -> 1 | Q6: =IF(F6=0,99999,F6) -> 99999 | R6: =IF(G6=0,99999,G6) -> 99999
B7: Feb-2026 | C7: =COUNTIFS(Orders!$Q$2:$Q$221,$B7,Orders!$Z$2:$Z$221,C$5) -> 3 | D7: =COUNTIFS(Orders!$Q$2:$Q$221,$B7,Orders!$Z$2:$Z$221,D$5) -> 2 | E7: =COUNTIFS(Orders!$Q$2:$Q$221,$B7,Orders!$Z$2:$Z$221,E$5) -> 2 | F7: =COUNTIFS(Orders!$Q$2:$Q$221,$B7,Orders!$Z$2:$Z$221,F$5) -> 0 | G7: =COUNTIFS(Orders!$Q$2:$Q$221,$B7,Orders!$Z$2:$Z$221,G$5) -> 0 | H7: =SUM(C7:G7) -> 7 | I7: =IF(H7=0,"No Losses",INDEX($C$5:$G$5,MATCH(MAX(C7:G7),C7:G7,0))) -> Order Cancelled | J7: =IF(H7=0,"No Losses",INDEX($C$5:$G$5,MATCH(MIN(N7:R7),N7:R7,0))) -> Order Returned | N7: =IF(C7=0,99999,C7) -> 3 | O7: =IF(D7=0,99999,D7) -> 2 | P7: =IF(E7=0,99999,E7) -> 2 | Q7: =IF(F7=0,99999,F7) -> 99999 | R7: =IF(G7=0,99999,G7) -> 99999
B8: Mar-2026 | C8: =COUNTIFS(Orders!$Q$2:$Q$221,$B8,Orders!$Z$2:$Z$221,C$5) -> 2 | D8: =COUNTIFS(Orders!$Q$2:$Q$221,$B8,Orders!$Z$2:$Z$221,D$5) -> 4 | E8: =COUNTIFS(Orders!$Q$2:$Q$221,$B8,Orders!$Z$2:$Z$221,E$5) -> 3 | F8: =COUNTIFS(Orders!$Q$2:$Q$221,$B8,Orders!$Z$2:$Z$221,F$5) -> 0 | G8: =COUNTIFS(Orders!$Q$2:$Q$221,$B8,Orders!$Z$2:$Z$221,G$5) -> 0 | H8: =SUM(C8:G8) -> 9 | I8: =IF(H8=0,"No Losses",INDEX($C$5:$G$5,MATCH(MAX(C8:G8),C8:G8,0))) -> Order Returned | J8: =IF(H8=0,"No Losses",INDEX($C$5:$G$5,MATCH(MIN(N8:R8),N8:R8,0))) -> Order Cancelled | N8: =IF(C8=0,99999,C8) -> 2 | O8: =IF(D8=0,99999,D8) -> 4 | P8: =IF(E8=0,99999,E8) -> 3 | Q8: =IF(F8=0,99999,F8) -> 99999 | R8: =IF(G8=0,99999,G8) -> 99999
B9: Apr-2026 | C9: =COUNTIFS(Orders!$Q$2:$Q$221,$B9,Orders!$Z$2:$Z$221,C$5) -> 3 | D9: =COUNTIFS(Orders!$Q$2:$Q$221,$B9,Orders!$Z$2:$Z$221,D$5) -> 2 | E9: =COUNTIFS(Orders!$Q$2:$Q$221,$B9,Orders!$Z$2:$Z$221,E$5) -> 2 | F9: =COUNTIFS(Orders!$Q$2:$Q$221,$B9,Orders!$Z$2:$Z$221,F$5) -> 0 | G9: =COUNTIFS(Orders!$Q$2:$Q$221,$B9,Orders!$Z$2:$Z$221,G$5) -> 0 | H9: =SUM(C9:G9) -> 7 | I9: =IF(H9=0,"No Losses",INDEX($C$5:$G$5,MATCH(MAX(C9:G9),C9:G9,0))) -> Order Cancelled | J9: =IF(H9=0,"No Losses",INDEX($C$5:$G$5,MATCH(MIN(N9:R9),N9:R9,0))) -> Order Returned | N9: =IF(C9=0,99999,C9) -> 3 | O9: =IF(D9=0,99999,D9) -> 2 | P9: =IF(E9=0,99999,E9) -> 2 | Q9: =IF(F9=0,99999,F9) -> 99999 | R9: =IF(G9=0,99999,G9) -> 99999
B10: May-2026 | C10: =COUNTIFS(Orders!$Q$2:$Q$221,$B10,Orders!$Z$2:$Z$221,C$5) -> 0 | D10: =COUNTIFS(Orders!$Q$2:$Q$221,$B10,Orders!$Z$2:$Z$221,D$5) -> 2 | E10: =COUNTIFS(Orders!$Q$2:$Q$221,$B10,Orders!$Z$2:$Z$221,E$5) -> 1 | F10: =COUNTIFS(Orders!$Q$2:$Q$221,$B10,Orders!$Z$2:$Z$221,F$5) -> 0 | G10: =COUNTIFS(Orders!$Q$2:$Q$221,$B10,Orders!$Z$2:$Z$221,G$5) -> 0 | H10: =SUM(C10:G10) -> 3 | I10: =IF(H10=0,"No Losses",INDEX($C$5:$G$5,MATCH(MAX(C10:G10),C10:G10,0))) -> Order Returned | J10: =IF(H10=0,"No Losses",INDEX($C$5:$G$5,MATCH(MIN(N10:R10),N10:R10,0))) -> High Discount | N10: =IF(C10=0,99999,C10) -> 99999 | O10: =IF(D10=0,99999,D10) -> 2 | P10: =IF(E10=0,99999,E10) -> 1 | Q10: =IF(F10=0,99999,F10) -> 99999 | R10: =IF(G10=0,99999,G10) -> 99999
B11: Jun-2026 | C11: =COUNTIFS(Orders!$Q$2:$Q$221,$B11,Orders!$Z$2:$Z$221,C$5) -> 1 | D11: =COUNTIFS(Orders!$Q$2:$Q$221,$B11,Orders!$Z$2:$Z$221,D$5) -> 3 | E11: =COUNTIFS(Orders!$Q$2:$Q$221,$B11,Orders!$Z$2:$Z$221,E$5) -> 1 | F11: =COUNTIFS(Orders!$Q$2:$Q$221,$B11,Orders!$Z$2:$Z$221,F$5) -> 0 | G11: =COUNTIFS(Orders!$Q$2:$Q$221,$B11,Orders!$Z$2:$Z$221,G$5) -> 0 | H11: =SUM(C11:G11) -> 5 | I11: =IF(H11=0,"No Losses",INDEX($C$5:$G$5,MATCH(MAX(C11:G11),C11:G11,0))) -> Order Returned | J11: =IF(H11=0,"No Losses",INDEX($C$5:$G$5,MATCH(MIN(N11:R11),N11:R11,0))) -> Order Cancelled | N11: =IF(C11=0,99999,C11) -> 1 | O11: =IF(D11=0,99999,D11) -> 3 | P11: =IF(E11=0,99999,E11) -> 1 | Q11: =IF(F11=0,99999,F11) -> 99999 | R11: =IF(G11=0,99999,G11) -> 99999
B12: Total | C12: =SUM(C6:C11) -> 12 | D12: =SUM(D6:D11) -> 16 | E12: =SUM(E6:E11) -> 10 | F12: =SUM(F6:F11) -> 0 | G12: =SUM(G6:G11) -> 0 | H12: =SUM(H6:H11) -> 38
B15: Total Loss Amount by Cause (All Months)
B16: Cause | C16: Number of Orders | D16: Total Loss ($) | E16: Avg Loss per Order ($)
B17: Order Cancelled | C17: =COUNTIF(Orders!$Z$2:$Z$221,B17) -> 12 | D17: =SUMIF(Orders!$Z$2:$Z$221,B17,Orders!$X$2:$X$221) -> 180 | E17: =IFERROR(D17/C17,0) -> 15
B18: Order Returned | C18: =COUNTIF(Orders!$Z$2:$Z$221,B18) -> 16 | D18: =SUMIF(Orders!$Z$2:$Z$221,B18,Orders!$X$2:$X$221) -> 31280.265 | E18: =IFERROR(D18/C18,0) -> 1955.0166
B19: High Discount | C19: =COUNTIF(Orders!$Z$2:$Z$221,B19) -> 10 | D19: =SUMIF(Orders!$Z$2:$Z$221,B19,Orders!$X$2:$X$221) -> 3181.9695 | E19: =IFERROR(D19/C19,0) -> 318.19695
B20: Delivery Cost Exceeded Order Value | C20: =COUNTIF(Orders!$Z$2:$Z$221,B20) -> 0 | D20: =SUMIF(Orders!$Z$2:$Z$221,B20,Orders!$X$2:$X$221) -> 0 | E20: =IFERROR(D20/C20,0) -> 0
B21: Low Order Value / Thin Margin | C21: =COUNTIF(Orders!$Z$2:$Z$221,B21) -> 0 | D21: =SUMIF(Orders!$Z$2:$Z$221,B21,Orders!$X$2:$X$221) -> 0 | E21: =IFERROR(D21/C21,0) -> 0
B22: Total | C22: =SUM(C17:C21) -> 38 | D22: =SUM(D17:D21) -> 34642.234

Sheet Dashboard
AF2: =IFERROR(GETPIVOTDATA("Sum of Net Revenue",Pivot!$A$25),0) -> 382675.05
AF3: =IFERROR(GETPIVOTDATA("Sum of Net Profit",Pivot!$A$25),0) -> 42519.871
AF4: =IFERROR(AF3/AF2,0) -> 0.11111221
AF5: =IFERROR(GETPIVOTDATA("Count of Orders",Pivot!$A$25),0) -> 220
AF6: =IFERROR(GETPIVOTDATA("Average of Delivery Time",Pivot!$A$25),0) -> 56.524038
AF7: =IFERROR(GETPIVOTDATA("Average of Rating",Pivot!$A$25),0) -> 3.9038462

Sheet Orders
A1: Order ID | B1: Order Date | C1: Customer Name | D1: City | E1: Channel | F1: Category | G1: Items | H1: Order Value ($) | I1: Discount % | J1: Delivery Charge ($) | K1: Net Revenue ($) | L1: Payment Method | M1: Delivery Partner | N1: Delivery Status | O1: Delivery Time (mins) | P1: Customer Rating (1-5) | Q1: Month | R1: Cost of Goods ($) | S1: Fulfillment Cost ($) | T1: Total Cost ($) | U1: Net Profit/(Loss) ($) | V1: Profit ($) | W1: Profit % | X1: Loss ($) | Y1: Loss % | Z1: Loss Cause
A2: ORD10206 | B2: 46024.935 | C2: Isha Das | D2: Hyderabad | E2: Mobile App | F2: Grocery | G2: 6 | H2: 1031.55 | I2: 0 | J2: 0 | K2: =IF(N2="Cancelled",0,IF(N2="Returned",J2,H2*(1-I2)+J2)) -> 1031.55 | L2: Cash on Delivery | M2: Jyoti Panda | N2: Delivered | O2: 66 | P2: 5 | Q2: =TEXT(tblOrders[[#This Row],[Order Date]],"mmm-yyyy") -> Jan-2026 | R2: =IF(N2="Cancelled",0,H2*INDEX(Assumptions!$C$7:$C$12,MATCH(F2,Assumptions!$B$7:$B$12,0))) -> 804.609 | S2: =IF(N2="Cancelled",Assumptions!$C$19,IF(N2="Returned",Assumptions!$C$17+O2*Assumptions!$C$18+Assumptions!$C$20,Assumptions!$C$17+O2*Assumptions!$C$18)) -> 44.8 | T2: =R2+S2 -> 849.409 | U2: =K2-T2 -> 182.141 | V2: =IF(U2>0,U2,0) -> 182.141 | W2: =IF(U2>0,U2/H2,0) -> 0.17657021 | X2: =IF(U2<0,-U2,0) -> 0 | Y2: =IF(U2<0,-U2/H2,0) -> 0 | Z2: =IF(U2>=0,"Profitable",IF(N2="Cancelled","Order Cancelled",IF(N2="Returned","Order Returned",IF(AND(I2>=0.15,U2<0),"High Discount",IF(S2>H2,"Delivery Cost Exceeded Order Value","Low Order Value / Thin Margin"))))) -> Profitable
A3: ORD10159 | B3: 46026.356 | C3: Sneha Das | D3: Chennai | E3: Mobile App | F3: Food & Beverage | G3: 3 | H3: 113.71 | I3: 0.2 | J3: 59 | K3: =IF(N3="Cancelled",0,IF(N3="Returned",J3,H3*(1-I3)+J3)) -> 149.968 | L3: Credit/Debit Card | M3: Deepak Sahu | N3: Delivered | O3: 30 | P3: 5 | Q3: =TEXT(tblOrders[[#This Row],[Order Date]],"mmm-yyyy") -> Jan-2026 | R3: =IF(N3="Cancelled",0,H3*INDEX(Assumptions!$C$7:$C$12,MATCH(F3,Assumptions!$B$7:$B$12,0))) -> 51.1695 | S3: =IF(N3="Cancelled",Assumptions!$C$19,IF(N3="Returned",Assumptions!$C$17+O3*Assumptions!$C$18+Assumptions!$C$20,Assumptions!$C$17+O3*Assumptions!$C$18)) -> 34 | T3: =R3+S3 -> 85.1695 | U3: =K3-T3 -> 64.7985 | V3: =IF(U3>0,U3,0) -> 64.7985 | W3: =IF(U3>0,U3/H3,0) -> 0.56985753 | X3: =IF(U3<0,-U3,0) -> 0 | Y3: =IF(U3<0,-U3/H3,0) -> 0 | Z3: =IF(U3>=0,"Profitable",IF(N3="Cancelled","Order Cancelled",IF(N3="Returned","Order Returned",IF(AND(I3>=0.15,U3<0),"High Discount",IF(S3>H3,"Delivery Cost Exceeded Order Value","Low Order Value / Thin Margin"))))) -> Profitable
A4: ORD10039 | B4: 46026.893 | C4: Riya Pillai | D4: Kolkata | E4: Mobile App | F4: Pharmacy | G4: 3 | H4: 982.53 | I4: 0.2 | J4: 59 | K4: =IF(N4="Cancelled",0,IF(N4="Returned",J4,H4*(1-I4)+J4)) -> 845.024 | L4: Credit/Debit Card | M4: Imran Khan | N4: Delivered | O4: 84 | P4: 5 | Q4: =TEXT(tblOrders[[#This Row],[Order Date]],"mmm-yyyy") -> Jan-2026 | R4: =IF(N4="Cancelled",0,H4*INDEX(Assumptions!$C$7:$C$12,MATCH(F4,Assumptions!$B$7:$B$12,0))) -> 687.771 | S4: =IF(N4="Cancelled",Assumptions!$C$19,IF(N4="Returned",Assumptions!$C$17+O4*Assumptions!$C$18+Assumptions!$C$20,Assumptions!$C$17+O4*Assumptions!$C$18)) -> 50.2 | T4: =R4+S4 -> 737.971 | U4: =K4-T4 -> 107.053 | V4: =IF(U4>0,U4,0) -> 107.053 | W4: =IF(U4>0,U4/H4,0) -> 0.10895647 | X4: =IF(U4<0,-U4,0) -> 0 | Y4: =IF(U4<0,-U4/H4,0) -> 0 | Z4: =IF(U4>=0,"Profitable",IF(N4="Cancelled","Order Cancelled",IF(N4="Returned","Order Returned",IF(AND(I4>=0.15,U4<0),"High Discount",IF(S4>H4,"Delivery Cost Exceeded Order Value","Low Order Value / Thin Margin"))))) -> Profitable
A5: ORD10167 | B5: 46029.39 | C5: Ishaan Iyer | D5: Bengaluru | E5: Mobile App | F5: Fashion | G5: 3 | H5: 3495.76 | I5: 0 | J5: 0 | K5: =IF(N5="Cancelled",0,IF(N5="Returned",J5,H5*(1-I5)+J5)) -> 3495.76 | L5: Cash on Delivery | M5: Sunil Barik | N5: Delivered | O5: 28 | P5: 5 | Q5: =TEXT(tblOrders[[#This Row],[Order Date]],"mmm-yyyy") -> Jan-2026 | R5: =IF(N5="Cancelled",0,H5*INDEX(Assumptions!$C$7:$C$12,MATCH(F5,Assumptions!$B$7:$B$12,0))) -> 1922.668 | S5: =IF(N5="Cancelled",Assumptions!$C$19,IF(N5="Returned",Assumptions!$C$17+O5*Assumptions!$C$18+Assumptions!$C$20,Assumptions!$C$17+O5*Assumptions!$C$18)) -> 33.4 | T5: =R5+S5 -> 1956.068 | U5: =K5-T5 -> 1539.692 | V5: =IF(U5>0,U5,0) -> 1539.692 | W5: =IF(U5>0,U5/H5,0) -> 0.44044557 | X5: =IF(U5<0,-U5,0) -> 0 | Y5: =IF(U5<0,-U5/H5,0) -> 0 | Z5: =IF(U5>=0,"Profitable",IF(N5="Cancelled","Order Cancelled",IF(N5="Returned","Order Returned",IF(AND(I5>=0.15,U5<0),"High Discount",IF(S5>H5,"Delivery Cost Exceeded Order Value","Low Order Value / Thin Margin"))))) -> Profitable
A6: ORD10041 | B6: 46030.662 | C6: Pooja Sharma | D6: Hyderabad | E6: Mobile App | F6: Electronics | G6: 3 | H6: 12129.22 | I6: 0 | J6: 0 | K6: =IF(N6="Cancelled",0,IF(N6="Returned",J6,H6*(1-I6)+J6)) -> 0 | L6: Cash on Delivery | M6: Imran Khan | N6: Cancelled | Q6: =TEXT(tblOrders[[#This Row],[Order Date]],"mmm-yyyy") -> Jan-2026 | R6: =IF(N6="Cancelled",0,H6*INDEX(Assumptions!$C$7:$C$12,MATCH(F6,Assumptions!$B$7:$B$12,0))) -> 0 | S6: =IF(N6="Cancelled",Assumptions!$C$19,IF(N6="Returned",Assumptions!$C$17+O6*Assumptions!$C$18+Assumptions!$C$20,Assumptions!$C$17+O6*Assumptions!$C$18)) -> 15 | T6: =R6+S6 -> 15 | U6: =K6-T6 -> -15 | V6: =IF(U6>0,U6,0) -> 0 | W6: =IF(U6>0,U6/H6,0) -> 0 | X6: =IF(U6<0,-U6,0) -> 15 | Y6: =IF(U6<0,-U6/H6,0) -> 0.001236683 | Z6: =IF(U6>=0,"Profitable",IF(N6="Cancelled","Order Cancelled",IF(N6="Returned","Order Returned",IF(AND(I6>=0.15,U6<0),"High Discount",IF(S6>H6,"Delivery Cost Exceeded Order Value","Low Order Value / Thin Margin"))))) -> Order Cancelled
A7: ORD10203 | B7: 46034.641 | C7: Arjun Patel | D7: Delhi | E7: Mobile App | F7: Electronics | G7: 1 | H7: 8650.68 | I7: 0.15 | J7: 0 | K7: =IF(N7="Cancelled",0,IF(N7="Returned",J7,H7*(1-I7)+J7)) -> 7353.078 | L7: Net Banking | M7: Kunal Mehta | N7: Delivered | O7: 49 | P7: 4 | Q7: =TEXT(tblOrders[[#This Row],[Order Date]],"mmm-yyyy") -> Jan-2026 | R7: =IF(N7="Cancelled",0,H7*INDEX(Assumptions!$C$7:$C$12,MATCH(F7,Assumptions!$B$7:$B$12,0))) -> 7612.5984 | S7: =IF(N7="Cancelled",Assumptions!$C$19,IF(N7="Returned",Assumptions!$C$17+O7*Assumptions!$C$18+Assumptions!$C$20,Assumptions!$C$17+O7*Assumptions!$C$18)) -> 39.7 | T7: =R7+S7 -> 7652.2984 | U7: =K7-T7 -> -299.2204 | V7: =IF(U7>0,U7,0) -> 0 | W7: =IF(U7>0,U7/H7,0) -> 0 | X7: =IF(U7<0,-U7,0) -> 299.2204 | Y7: =IF(U7<0,-U7/H7,0) -> 0.034589235 | Z7: =IF(U7>=0,"Profitable",IF(N7="Cancelled","Order Cancelled",IF(N7="Returned","Order Returned",IF(AND(I7>=0.15,U7<0),"High Discount",IF(S7>H7,"Delivery Cost Exceeded Order Value","Low Order Value / Thin Margin"))))) -> High Discount
A8: ORD10029 | B8: 46035.677 | C8: Divya Pillai | D8: Kolkata | E8: Mobile App | F8: Home & Living | G8: 2 | H8: 4848.22 | I8: 0.15 | J8: 0 | K8: =IF(N8="Cancelled",0,IF(N8="Returned",J8,H8*(1-I8)+J8)) -> 0 | L8: Cash on Delivery | M8: Rekha Sethi | N8: Returned | O8: 74 | P8: 3 | Q8: =TEXT(tblOrders[[#This Row],[Order Date]],"mmm-yyyy") -> Jan-2026 | R8: =IF(N8="Cancelled",0,H8*INDEX(Assumptions!$C$7:$C$12,MATCH(F8,Assumptions!$B$7:$B$12,0))) -> 3151.343 | S8: =IF(N8="Cancelled",Assumptions!$C$19,IF(N8="Returned",Assumptions!$C$17+O8*Assumptions!$C$18+Assumptions!$C$20,Assumptions!$C$17+O8*Assumptions!$C$18)) -> 67.2 | T8: =R8+S8 -> 3218.543 | U8: =K8-T8 -> -3218.543 | V8: =IF(U8>0,U8,0) -> 0 | W8: =IF(U8>0,U8/H8,0) -> 0 | X8: =IF(U8<0,-U8,0) -> 3218.543 | Y8: =IF(U8<0,-U8/H8,0) -> 0.66386076 | Z8: =IF(U8>=0,"Profitable",IF(N8="Cancelled","Order Cancelled",IF(N8="Returned","Order Returned",IF(AND(I8>=0.15,U8<0),"High Discount",IF(S8>H8,"Delivery Cost Exceeded Order Value","Low Order Value / Thin Margin"))))) -> Order Returned
A9: ORD10013 | B9: 46035.729 | C9: Yash Reddy | D9: Hyderabad | E9: Website | F9: Fashion | G9: 2 | H9: 510.45 | I9: 0.1 | J9: 29 | K9: =IF(N9="Cancelled",0,IF(N9="Returned",J9,H9*(1-I9)+J9)) -> 488.405 | L9: Credit/Debit Card | M9: Harpreet Singh | N9: Delivered | O9: 26 | P9: 5 | Q9: =TEXT(tblOrders[[#This Row],[Order Date]],"mmm-yyyy") -> Jan-2026 | R9: =IF(N9="Cancelled",0,H9*INDEX(Assumptions!$C$7:$C$12,MATCH(F9,Assumptions!$B$7:$B$12,0))) -> 280.7475 | S9: =IF(N9="Cancelled",Assumptions!$C$19,IF(N9="Returned",Assumptions!$C$17+O9*Assumptions!$C$18+Assumptions!$C$20,Assumptions!$C$17+O9*Assumptions!$C$18)) -> 32.8 | T9: =R9+S9 -> 313.5475 | U9: =K9-T9 -> 174.8575 | V9: =IF(U9>0,U9,0) -> 174.8575 | W9: =IF(U9>0,U9/H9,0) -> 0.34255559 | X9: =IF(U9<0,-U9,0) -> 0 | Y9: =IF(U9<0,-U9/H9,0) -> 0 | Z9: =IF(U9>=0,"Profitable",IF(N9="Cancelled","Order Cancelled",IF(N9="Returned","Order Returned",IF(AND(I9>=0.15,U9<0),"High Discount",IF(S9>H9,"Delivery Cost Exceeded Order Value","Low Order Value / Thin Margin"))))) -> Profitable
A10: ORD10084 | B10: 46036.424 | C10: Aryan Joshi | D10: Pune | E10: Mobile App | F10: Food & Beverage | G10: 1 | H10: 317.68 | I10: 0.15 | J10: 59 | K10: =IF(N10="Cancelled",0,IF(N10="Returned",J10,H10*(1-I10)+J10)) -> 329.028 | L10: Net Banking | M10: Gaurav Nanda | N10: Delivered | O10: 71 | P10: 4 | Q10: =TEXT(tblOrders[[#This Row],[Order Date]],"mmm-yyyy") -> Jan-2026 | R10: =IF(N10="Cancelled",0,H10*INDEX(Assumptions!$C$7:$C$12,MATCH(F10,Assumptions!$B$7:$B$12,0))) -> 142.956 | S10: =IF(N10="Cancelled",Assumptions!$C$19,IF(N10="Returned",Assumptions!$C$17+O10*Assumptions!$C$18+Assumptions!$C$20,Assumptions!$C$17+O10*Assumptions!$C$18)) -> 46.3 | T10: =R10+S10 -> 189.256 | U10: =K10-T10 -> 139.772 | V10: =IF(U10>0,U10,0) -> 139.772 | W10: =IF(U10>0,U10/H10,0) -> 0.43997734 | X10: =IF(U10<0,-U10,0) -> 0 | Y10: =IF(U10<0,-U10/H10,0) -> 0 | Z10: =IF(U10>=0,"Profitable",IF(N10="Cancelled","Order Cancelled",IF(N10="Returned","Order Returned",IF(AND(I10>=0.15,U10<0),"High Discount",IF(S10>H10,"Delivery Cost Exceeded Order Value","Low Order Value / Thin Margin"))))) -> Profitable
A11: ORD10153 | B11: 46041.494 | C11: Simran Reddy | D11: Kolkata | E11: Website | F11: Food & Beverage | G11: 5 | H11: 273.61 | I11: 0 | J11: 49 | K11: =IF(N11="Cancelled",0,IF(N11="Returned",J11,H11*(1-I11)+J11)) -> 49 | L11: Cash on Delivery | M11: Gaurav Nanda | N11: Returned | O11: 19 | P11: 1 | Q11: =TEXT(tblOrders[[#This Row],[Order Date]],"mmm-yyyy") -> Jan-2026 | R11: =IF(N11="Cancelled",0,H11*INDEX(Assumptions!$C$7:$C$12,MATCH(F11,Assumptions!$B$7:$B$12,0))) -> 123.1245 | S11: =IF(N11="Cancelled",Assumptions!$C$19,IF(N11="Returned",Assumptions!$C$17+O11*Assumptions!$C$18+Assumptions!$C$20,Assumptions!$C$17+O11*Assumptions!$C$18)) -> 50.7 | T11: =R11+S11 -> 173.8245 | U11: =K11-T11 -> -124.8245 | V11: =IF(U11>0,U11,0) -> 0 | W11: =IF(U11>0,U11/H11,0) -> 0 | X11: =IF(U11<0,-U11,0) -> 124.8245 | Y11: =IF(U11<0,-U11/H11,0) -> 0.45621322 | Z11: =IF(U11>=0,"Profitable",IF(N11="Cancelled","Order Cancelled",IF(N11="Returned","Order Returned",IF(AND(I11>=0.15,U11<0),"High Discount",IF(S11>H11,"Delivery Cost Exceeded Order Value","Low Order Value / Thin Margin"))))) -> Order Returned
A12: ORD10008 | B12: 46041.819 | C12: Rohan Agarwal | D12: Kolkata | E12: Mobile App | F12: Grocery | G12: 1 | H12: 1052.62 | I12: 0 | J12: 0 | K12: =IF(N12="Cancelled",0,IF(N12="Returned",J12,H12*(1-I12)+J12)) -> 1052.62 | L12: Credit/Debit Card | M12: Sunil Barik | N12: Delivered | O12: 80 | P12: 3 | Q12: =TEXT(tblOrders[[#This Row],[Order Date]],"mmm-yyyy") -> Jan-2026 | R12: =IF(N12="Cancelled",0,H12*INDEX(Assumptions!$C$7:$C$12,MATCH(F12,Assumptions!$B$7:$B$12,0))) -> 821.0436 | S12: =IF(N12="Cancelled",Assumptions!$C$19,IF(N12="Returned",Assumptions!$C$17+O12*Assumptions!$C$18+Assumptions!$C$20,Assumptions!$C$17+O12*Assumptions!$C$18)) -> 49 | T12: =R12+S12 -> 870.0436 | U12: =K12-T12 -> 182.5764 | V12: =IF(U12>0,U12,0) -> 182.5764 | W12: =IF(U12>0,U12/H12,0) -> 0.17344949 | X12: =IF(U12<0,-U12,0) -> 0 | Y12: =IF(U12<0,-U12/H12,0) -> 0 | Z12: =IF(U12>=0,"Profitable",IF(N12="Cancelled","Order Cancelled",IF(N12="Returned","Order Returned",IF(AND(I12>=0.15,U12<0),"High Discount",IF(S12>H12,"Delivery Cost Exceeded Order Value","Low Order Value / Thin Margin"))))) -> Profitable
A13: ORD10192 | B13: 46042.442 | C13: Yash Patel | D13: Pune | E13: Mobile App | F13: Grocery | G13: 1 | H13: 158.47 | I13: 0 | J13: 29 | K13: =IF(N13="Cancelled",0,IF(N13="Returned",J13,H13*(1-I13)+J13)) -> 187.47 | L13: Net Banking | M13: Harpreet Singh | N13: Delivered | O13: 79 | P13: 3 | Q13: =TEXT(tblOrders[[#This Row],[Order Date]],"mmm-yyyy") -> Jan-2026 | R13: =IF(N13="Cancelled",0,H13*INDEX(Assumptions!$C$7:$C$12,MATCH(F13,Assumptions!$B$7:$B$12,0))) -> 123.6066 | S13: =IF(N13="Cancelled",Assumptions!$C$19,IF(N13="Returned",Assumptions!$C$17+O13*Assumptions!$C$18+Assumptions!$C$20,Assumptions!$C$17+O13*Assumptions!$C$18)) -> 48.7 | T13: =R13+S13 -> 172.3066 | U13: =K13-T13 -> 15.1634 | V13: =IF(U13>0,U13,0) -> 15.1634 | W13: =IF(U13>0,U13/H13,0) -> 0.09568625 | X13: =IF(U13<0,-U13,0) -> 0 | Y13: =IF(U13<0,-U13/H13,0) -> 0 | Z13: =IF(U13>=0,"Profitable",IF(N13="Cancelled","Order Cancelled",IF(N13="Returned","Order Returned",IF(AND(I13>=0.15,U13<0),"High Discount",IF(S13>H13,"Delivery Cost Exceeded Order Value","Low Order Value / Thin Margin"))))) -> Profitable
A14: ORD10208 | B14: 46042.733 | C14: Arjun Iyer | D14: Pune | E14: Mobile App | F14: Grocery | G14: 2 | H14: 398.61 | I14: 0 | J14: 49 | K14: =IF(N14="Cancelled",0,IF(N14="Returned",J14,H14*(1-I14)+J14)) -> 447.61 | L14: Net Banking | M14: Omkar Naik | N14: Delivered | O14: 59 | P14: 4 | Q14: =TEXT(tblOrders[[#This Row],[Order Date]],"mmm-yyyy") -> Jan-2026 | R14: =IF(N14="Cancelled",0,H14*INDEX(Assumptions!$C$7:$C$12,MATCH(F14,Assumptions!$B$7:$B$12,0))) -> 310.9158 | S14: =IF(N14="Cancelled",Assumptions!$C$19,IF(N14="Returned",Assumptions!$C$17+O14*Assumptions!$C$18+Assumptions!$C$20,Assumptions!$C$17+O14*Assumptions!$C$18)) -> 42.7 | T14: =R14+S14 -> 353.6158 | U14: =K14-T14 -> 93.9942 | V14: =IF(U14>0,U14,0) -> 93.9942 | W14: =IF(U14>0,U14/H14,0) -> 0.23580492 | X14: =IF(U14<0,-U14,0) -> 0 | Y14: =IF(U14<0,-U14/H14,0) -> 0 | Z14: =IF(U14>=0,"Profitable",IF(N14="Cancelled","Order Cancelled",IF(N14="Returned","Order Returned",IF(AND(I14>=0.15,U14<0),"High Discount",IF(S14>H14,"Delivery Cost Exceeded Order Value","Low Order Value / Thin Margin"))))) -> Profitable
A15: ORD10143 | B15: 46042.942 | C15: Tanya Das | D15: Kolkata | E15: Website | F15: Grocery | G15: 5 | H15: 362.26 | I15: 0.1 | J15: 39 | K15: =IF(N15="Cancelled",0,IF(N15="Returned",J15,H15*(1-I15)+J15)) -> 365.034 | L15: Credit/Debit Card | M15: Bikash Mallick | N15: Delivered | O15: 84 | P15: 4 | Q15: =TEXT(tblOrders[[#This Row],[Order Date]],"mmm-yyyy") -> Jan-2026 | R15: =IF(N15="Cancelled",0,H15*INDEX(Assumptions!$C$7:$C$12,MATCH(F15,Assumptions!$B$7:$B$12,0))) -> 282.5628 | S15: =IF(N15="Cancelled",Assumptions!$C$19,IF(N15="Returned",Assumptions!$C$17+O15*Assumptions!$C$18+Assumptions!$C$20,Assumptions!$C$17+O15*Assumptions!$C$18)) -> 50.2 | T15: =R15+S15 -> 332.7628 | U15: =K15-T15 -> 32.2712 | V15: =IF(U15>0,U15,0) -> 32.2712 | W15: =IF(U15>0,U15/H15,0) -> 0.089082979 | X15: =IF(U15<0,-U15,0) -> 0 | Y15: =IF(U15<0,-U15/H15,0) -> 0 | Z15: =IF(U15>=0,"Profitable",IF(N15="Cancelled","Order Cancelled",IF(N15="Returned","Order Returned",IF(AND(I15>=0.15,U15<0),"High Discount",IF(S15>H15,"Delivery Cost Exceeded Order Value","Low Order Value / Thin Margin"))))) -> Profitable
A16: ORD10019 | B16: 46042.947 | C16: Ishaan Bose | D16: Hyderabad | E16: Mobile App | F16: Home & Living | G16: 3 | H16: 3578.56 | I16: 0 | J16: 0 | K16: =IF(N16="Cancelled",0,IF(N16="Returned",J16,H16*(1-I16)+J16)) -> 3578.56 | L16: Net Banking | M16: Ramesh Yadav | N16: Delivered | O16: 57 | P16: 4 | Q16: =TEXT(tblOrders[[#This Row],[Order Date]],"mmm-yyyy") -> Jan-2026 | R16: =IF(N16="Cancelled",0,H16*INDEX(Assumptions!$C$7:$C$12,MATCH(F16,Assumptions!$B$7:$B$12,0))) -> 2326.064 | S16: =IF(N16="Cancelled",Assumptions!$C$19,IF(N16="Returned",Assumptions!$C$17+O16*Assumptions!$C$18+Assumptions!$C$20,Assumptions!$C$17+O16*Assumptions!$C$18)) -> 42.1 | T16: =R16+S16 -> 2368.164 | U16: =K16-T16 -> 1210.396 | V16: =IF(U16>0,U16,0) -> 1210.396 | W16: =IF(U16>0,U16/H16,0) -> 0.33823549 | X16: =IF(U16<0,-U16,0) -> 0 | Y16: =IF(U16<0,-U16/H16,0) -> 0 | Z16: =IF(U16>=0,"Profitable",IF(N16="Cancelled","Order Cancelled",IF(N16="Returned","Order Returned",IF(AND(I16>=0.15,U16<0),"High Discount",IF(S16>H16,"Delivery Cost Exceeded Order Value","Low Order Value / Thin Margin"))))) -> Profitable
A17: ORD10077 | B17: 46043.568 | C17: Sahil Ghosh | D17: Mumbai | E17: Mobile App | F17: Grocery | G17: 5 | H17: 814.73 | I17: 0.1 | J17: 49 | K17: =IF(N17="Cancelled",0,IF(N17="Returned",J17,H17*(1-I17)+J17)) -> 49 | L17: Net Banking | M17: Omkar Naik | N17: Returned | O17: 85 | P17: 2 | Q17: =TEXT(tblOrders[[#This Row],[Order Date]],"mmm-yyyy") -> Jan-2026 | R17: =IF(N17="Cancelled",0,H17*INDEX(Assumptions!$C$7:$C$12,MATCH(F17,Assumptions!$B$7:$B$12,0))) -> 635.4894 | S17: =IF(N17="Cancelled",Assumptions!$C$19,IF(N17="Returned",Assumptions!$C$17+O17*Assumptions!$C$18+Assumptions!$C$20,Assumptions!$C$17+O17*Assumptions!$C$18)) -> 70.5 | T17: =R17+S17 -> 705.9894 | U17: =K17-T17 -> -656.9894 | V17: =IF(U17>0,U17,0) -> 0 | W17: =IF(U17>0,U17/H17,0) -> 0 | X17: =IF(U17<0,-U17,0) -> 656.9894 | Y17: =IF(U17<0,-U17/H17,0) -> 0.80638911 | Z17: =IF(U17>=0,"Profitable",IF(N17="Cancelled","Order Cancelled",IF(N17="Returned","Order Returned",IF(AND(I17>=0.15,U17<0),"High Discount",IF(S17>H17,"Delivery Cost Exceeded Order Value","Low Order Value / Thin Margin"))))) -> Order Returned
A18: ORD10042 | B18: 46044.49 | C18: Sneha Kapoor | D18: Hyderabad | E18: Mobile App | F18: Fashion | G18: 2 | H18: 2855.25 | I18: 0.15 | J18: 0 | K18: =IF(N18="Cancelled",0,IF(N18="Returned",J18,H18*(1-I18)+J18)) -> 2426.9625 | L18: Net Banking | M18: Jyoti Panda | N18: Delivered | O18: 20 | P18: 3 | Q18: =TEXT(tblOrders[[#This Row],[Order Date]],"mmm-yyyy") -> Jan-2026 | R18: =IF(N18="Cancelled",0,H18*INDEX(Assumptions!$C$7:$C$12,MATCH(F18,Assumptions!$B$7:$B$12,0))) -> 1570.3875 | S18: =IF(N18="Cancelled",Assumptions!$C$19,IF(N18="Returned",Assumptions!$C$17+O18*Assumptions!$C$18+Assumptions!$C$20,Assumptions!$C$17+O18*Assumptions!$C$18)) -> 31 | T18: =R18+S18 -> 1601.3875 | U18: =K18-T18 -> 825.575 | V18: =IF(U18>0,U18,0) -> 825.575 | W18: =IF(U18>0,U18/H18,0) -> 0.28914281 | X18: =IF(U18<0,-U18,0) -> 0 | Y18: =IF(U18<0,-U18/H18,0) -> 0 | Z18: =IF(U18>=0,"Profitable",IF(N18="Cancelled","Order Cancelled",IF(N18="Returned","Order Returned",IF(AND(I18>=0.15,U18<0),"High Discount",IF(S18>H18,"Delivery Cost Exceeded Order Value","Low Order Value / Thin Margin"))))) -> Profitable
... A29: ORD10062 | B29: 46048.861 | C29: Divya Nair | D29: Hyderabad | E29: Mobile App | F29: Food & Beverage | G29: 2 | H29: 655.2 | I29: 0 | J29: 29 | K29: =IF(N29="Cancelled",0,IF(N29="Returned",J29,H29*(1-I29)+J29)) -> 684.2 | L29: Cash on Delivery | M29: Lalita Rout | N29: Delivered | O29: 55 | P29: 4 | Q29: =TEXT(tblOrders[[#This Row],[Order Date]],"mmm-yyyy") -> Jan-2026 | R29: =IF(N29="Cancelled",0,H29*INDEX(Assumptions!$C$7:$C$12,MATCH(F29,Assumptions!$B$7:$B$12,0))) -> 294.84 | S29: =IF(N29="Cancelled",Assumptions!$C$19,IF(N29="Returned",Assumptions!$C$17+O29*Assumptions!$C$18+Assumptions!$C$20,Assumptions!$C$17+O29*Assumptions!$C$18)) -> 41.5 | T29: =R29+S29 -> 336.34 | U29: =K29-T29 -> 347.86 | V29: =IF(U29>0,U29,0) -> 347.86 | W29: =IF(U29>0,U29/H29,0) -> 0.53092186 | X29: =IF(U29<0,-U29,0) -> 0 | Y29: =IF(U29<0,-U29/H29,0) -> 0 | Z29: =IF(U29>=0,"Profitable",IF(N29="Cancelled","Order Cancelled",IF(N29="Returned","Order Returned",IF(AND(I29>=0.15,U29<0),"High Discount",IF(S29>H29,"Delivery Cost Exceeded Order Value","Low Order Value / Thin Margin"))))) -> Profitable
A30: ORD10078 | B30: 46048.864 | C30: Karan Malhotra | D30: Mumbai | E30: Mobile App | F30: Grocery | G30: 5 | H30: 906.88 | I30: 0 | J30: 59 | K30: =IF(N30="Cancelled",0,IF(N30="Returned",J30,H30*(1-I30)+J30)) -> 0 | L30: Net Banking | M30: Nisha Pradhan | N30: Cancelled | Q30: =TEXT(tblOrders[[#This Row],[Order Date]],"mmm-yyyy") -> Jan-2026 | R30: =IF(N30="Cancelled",0,H30*INDEX(Assumptions!$C$7:$C$12,MATCH(F30,Assumptions!$B$7:$B$12,0))) -> 0 | S30: =IF(N30="Cancelled",Assumptions!$C$19,IF(N30="Returned",Assumptions!$C$17+O30*Assumptions!$C$18+Assumptions!$C$20,Assumptions!$C$17+O30*Assumptions!$C$18)) -> 15 | T30: =R30+S30 -> 15 | U30: =K30-T30 -> -15 | V30: =IF(U30>0,U30,0) -> 0 | W30: =IF(U30>0,U30/H30,0) -> 0 | X30: =IF(U30<0,-U30,0) -> 15 | Y30: =IF(U30<0,-U30/H30,0) -> 0.016540226 | Z30: =IF(U30>=0,"Profitable",IF(N30="Cancelled","Order Cancelled",IF(N30="Returned","Order Returned",IF(AND(I30>=0.15,U30<0),"High Discount",IF(S30>H30,"Delivery Cost Exceeded Order Value","Low Order Value / Thin Margin"))))) -> Order Cancelled
A31: ORD10193 | B31: 46049.558 | C31: Rahul Bose | D31: Hyderabad | E31: Mobile App | F31: Pharmacy | G31: 2 | H31: 991.04 | I31: 0.15 | J31: 39 | K31: =IF(N31="Cancelled",0,IF(N31="Returned",J31,H31*(1-I31)+J31)) -> 881.384 | L31: UPI/Wallet | M31: Farhan Ali | N31: Delivered | O31: 19 | P31: 5 | Q31: =TEXT(tblOrders[[#This Row],[Order Date]],"mmm-yyyy") -> Jan-2026 | R31: =IF(N31="Cancelled",0,H31*INDEX(Assumptions!$C$7:$C$12,MATCH(F31,Assumptions!$B$7:$B$12,0))) -> 693.728 | S31: =IF(N31="Cancelled",Assumptions!$C$19,IF(N31="Returned",Assumptions!$C$17+O31*Assumptions!$C$18+Assumptions!$C$20,Assumptions!$C$17+O31*Assumptions!$C$18)) -> 30.7 | T31: =R31+S31 -> 724.428 | U31: =K31-T31 -> 156.956 | V31: =IF(U31>0,U31,0) -> 156.956 | W31: =IF(U31>0,U31/H31,0) -> 0.15837504 | X31: =IF(U31<0,-U31,0) -> 0 | Y31: =IF(U31<0,-U31/H31,0) -> 0 | Z31: =IF(U31>=0,"Profitable",IF(N31="Cancelled","Order Cancelled",IF(N31="Returned","Order Returned",IF(AND(I31>=0.15,U31<0),"High Discount",IF(S31>H31,"Delivery Cost Exceeded Order Value","Low Order Value / Thin Margin"))))) -> Profitable
A32: ORD10010 | B32: 46050.467 | C32: Dev Pillai | D32: Bhubaneswar | E32: Mobile App | F32: Grocery | G32: 4 | H32: 342.66 | I32: 0.05 | J32: 39 | K32: =IF(N32="Cancelled",0,IF(N32="Returned",J32,H32*(1-I32)+J32)) -> 364.527 | L32: UPI/Wallet | M32: Ramesh Yadav | N32: Delivered | O32: 88 | P32: 3 | Q32: =TEXT(tblOrders[[#This Row],[Order Date]],"mmm-yyyy") -> Jan-2026 | R32: =IF(N32="Cancelled",0,H32*INDEX(Assumptions!$C$7:$C$12,MATCH(F32,Assumptions!$B$7:$B$12,0))) -> 267.2748 | S32: =IF(N32="Cancelled",Assumptions!$C$19,IF(N32="Returned",Assumptions!$C$17+O32*Assumptions!$C$18+Assumptions!$C$20,Assumptions!$C$17+O32*Assumptions!$C$18)) -> 51.4 | T32: =R32+S32 -> 318.6748 | U32: =K32-T32 -> 45.8522 | V32: =IF(U32>0,U32,0) -> 45.8522 | W32: =IF(U32>0,U32/H32,0) -> 0.13381253 | X32: =IF(U32<0,-U32,0) -> 0 | Y32: =IF(U32<0,-U32/H32,0) -> 0 | Z32: =IF(U32>=0,"Profitable",IF(N32="Cancelled","Order Cancelled",IF(N32="Returned","Order Returned",IF(AND(I32>=0.15,U32<0),"High Discount",IF(S32>H32,"Delivery Cost Exceeded Order Value","Low Order Value / Thin Margin"))))) -> Profitable
A33: ORD10148 | B33: 46051.369 | C33: Yash Malhotra | D33: Hyderabad | E33: Mobile App | F33: Food & Beverage | G33: 1 | H33: 292.53 | I33: 0 | J33: 29 | K33: =IF(N33="Cancelled",0,IF(N33="Returned",J33,H33*(1-I33)+J33)) -> 321.53 | L33: UPI/Wallet | M33: Ramesh Yadav | N33: Delivered | O33: 24 | P33: 3 | Q33: =TEXT(tblOrders[[#This Row],[Order Date]],"mmm-yyyy") -> Jan-2026 | R33: =IF(N33="Cancelled",0,H33*INDEX(Assumptions!$C$7:$C$12,MATCH(F33,Assumptions!$B$7:$B$12,0))) -> 131.6385 | S33: =IF(N33="Cancelled",Assumptions!$C$19,IF(N33="Returned",Assumptions!$C$17+O33*Assumptions!$C$18+Assumptions!$C$20,Assumptions!$C$17+O33*Assumptions!$C$18)) -> 32.2 | T33: =R33+S33 -> 163.8385 | U33: =K33-T33 -> 157.6915 | V33: =IF(U33>0,U33,0) -> 157.6915 | W33: =IF(U33>0,U33/H33,0) -> 0.53906095 | X33: =IF(U33<0,-U33,0) -> 0 | Y33: =IF(U33<0,-U33/H33,0) -> 0 | Z33: =IF(U33>=0,"Profitable",IF(N33="Cancelled","Order Cancelled",IF(N33="Returned","Order Returned",IF(AND(I33>=0.15,U33<0),"High Discount",IF(S33>H33,"Delivery Cost Exceeded Order Value","Low Order Value / Thin Margin"))))) -> Profitable
A34: ORD10220 | B34: 46051.898 | C34: Rohan Gupta | D34: Mumbai | E34: Website | F34: Pharmacy | G34: 3 | H34: 1080.44 | I34: 0.15 | J34: 0 | K34: =IF(N34="Cancelled",0,IF(N34="Returned",J34,H34*(1-I34)+J34)) -> 918.374 | L34: Net Banking | M34: Kunal Mehta | N34: Delivered | O34: 61 | P34: 4 | Q34: =TEXT(tblOrders[[#This Row],[Order Date]],"mmm-yyyy") -> Jan-2026 | R34: =IF(N34="Cancelled",0,H34*INDEX(Assumptions!$C$7:$C$12,MATCH(F34,Assumptions!$B$7:$B$12,0))) -> 756.308 | S34: =IF(N34="Cancelled",Assumptions!$C$19,IF(N34="Returned",Assumptions!$C$17+O34*Assumptions!$C$18+Assumptions!$C$20,Assumptions!$C$17+O34*Assumptions!$C$18)) -> 43.3 | T34: =R34+S34 -> 799.608 | U34: =K34-T34 -> 118.766 | V34: =IF(U34>0,U34,0) -> 118.766 | W34: =IF(U34>0,U34/H34,0) -> 0.10992373 | X34: =IF(U34<0,-U34,0) -> 0 | Y34: =IF(U34<0,-U34/H34,0) -> 0 | Z34: =IF(U34>=0,"Profitable",IF(N34="Cancelled","Order Cancelled",IF(N34="Returned","Order Returned",IF(AND(I34>=0.15,U34<0),"High Discount",IF(S34>H34,"Delivery Cost Exceeded Order Value","Low Order Value / Thin Margin"))))) -> Profitable
A35: ORD10179 | B35: 46052.529 | C35: Varun Singh | D35: Pune | E35: Mobile App | F35: Pharmacy | G35: 6 | H35: 525.03 | I35: 0.05 | J35: 59 | K35: =IF(N35="Cancelled",0,IF(N35="Returned",J35,H35*(1-I35)+J35)) -> 557.7785 | L35: UPI/Wallet | M35: Farhan Ali | N35: Delivered | O35: 76 | P35: 5 | Q35: =TEXT(tblOrders[[#This Row],[Order Date]],"mmm-yyyy") -> Jan-2026 | R35: =IF(N35="Cancelled",0,H35*INDEX(Assumptions!$C$7:$C$12,MATCH(F35,Assumptions!$B$7:$B$12,0))) -> 367.521 | S35: =IF(N35="Cancelled",Assumptions!$C$19,IF(N35="Returned",Assumptions!$C$17+O35*Assumptions!$C$18+Assumptions!$C$20,Assumptions!$C$17+O35*Assumptions!$C$18)) -> 47.8 | T35: =R35+S35 -> 415.321 | U35: =K35-T35 -> 142.4575 | V35: =IF(U35>0,U35,0) -> 142.4575 | W35: =IF(U35>0,U35/H35,0) -> 0.27133211 | X35: =IF(U35<0,-U35,0) -> 0 | Y35: =IF(U35<0,-U35/H35,0) -> 0 | Z35: =IF(U35>=0,"Profitable",IF(N35="Cancelled","Order Cancelled",IF(N35="Returned","Order Returned",IF(AND(I35>=0.15,U35<0),"High Discount",IF(S35>H35,"Delivery Cost Exceeded Order Value","Low Order Value / Thin Margin"))))) -> Profitable
A36: ORD10050 | B36: 46052.676 | C36: Nikhil Kapoor | D36: Chennai | E36: Website | F36: Food & Beverage | G36: 2 | H36: 157.13 | I36: 0 | J36: 49 | K36: =IF(N36="Cancelled",0,IF(N36="Returned",J36,H36*(1-I36)+J36)) -> 206.13 | L36: Cash on Delivery | M36: Jyoti Panda | N36: Delivered | O36: 77 | P36: 5 | Q36: =TEXT(tblOrders[[#This Row],[Order Date]],"mmm-yyyy") -> Jan-2026 | R36: =IF(N36="Cancelled",0,H36*INDEX(Assumptions!$C$7:$C$12,MATCH(F36,Assumptions!$B$7:$B$12,0))) -> 70.7085 | S36: =IF(N36="Cancelled",Assumptions!$C$19,IF(N36="Returned",Assumptions!$C$17+O36*Assumptions!$C$18+Assumptions!$C$20,Assumptions!$C$17+O36*Assumptions!$C$18)) -> 48.1 | T36: =R36+S36 -> 118.8085 | U36: =K36-T36 -> 87.3215 | V36: =IF(U36>0,U36,0) -> 87.3215 | W36: =IF(U36>0,U36/H36,0) -> 0.55572774 | X36: =IF(U36<0,-U36,0) -> 0 | Y36: =IF(U36<0,-U36/H36,0) -> 0 | Z36: =IF(U36>=0,"Profitable",IF(N36="Cancelled","Order Cancelled",IF(N36="Returned","Order Returned",IF(AND(I36>=0.15,U36<0),"High Discount",IF(S36>H36,"Delivery Cost Exceeded Order Value","Low Order Value / Thin Margin"))))) -> Profitable
A37: ORD10017 | B37: 46052.921 | C37: Arjun Verma | D37: Pune | E37: Mobile App | F37: Food & Beverage | G37: 3 | H37: 583.86 | I37: 0.15 | J37: 49 | K37: =IF(N37="Cancelled",0,IF(N37="Returned",J37,H37*(1-I37)+J37)) -> 545.281 | L37: Credit/Debit Card | M37: Pankaj Dey | N37: Delivered | O37: 51 | P37: 5 | Q37: =TEXT(tblOrders[[#This Row],[Order Date]],"mmm-yyyy") -> Jan-2026 | R37: =IF(N37="Cancelled",0,H37*INDEX(Assumptions!$C$7:$C$12,MATCH(F37,Assumptions!$B$7:$B$12,0))) -> 262.737 | S37: =IF(N37="Cancelled",Assumptions!$C$19,IF(N37="Returned",Assumptions!$C$17+O37*Assumptions!$C$18+Assumptions!$C$20,Assumptions!$C$17+O37*Assumptions!$C$18)) -> 40.3 | T37: =R37+S37 -> 303.037 | U37: =K37-T37 -> 242.244 | V37: =IF(U37>0,U37,0) -> 242.244 | W37: =IF(U37>0,U37/H37,0) -> 0.41490083 | X37: =IF(U37<0,-U37,0) -> 0 | Y37: =IF(U37<0,-U37/H37,0) -> 0 | Z37: =IF(U37>=0,"Profitable",IF(N37="Cancelled","Order Cancelled",IF(N37="Returned","Order Returned",IF(AND(I37>=0.15,U37<0),"High Discount",IF(S37>H37,"Delivery Cost Exceeded Order Value","Low Order Value / Thin Margin"))))) -> Profitable
A38: ORD10210 | B38: 46053.382 | C38: Nikhil Iyer | D38: Delhi | E38: Mobile App | F38: Pharmacy | G38: 6 | H38: 1069.57 | I38: 0 | J38: 0 | K38: =IF(N38="Cancelled",0,IF(N38="Returned",J38,H38*(1-I38)+J38)) -> 1069.57 | L38: Credit/Debit Card | M38: Anita Behera | N38: Delivered | O38: 59 | P38: 3 | Q38: =TEXT(tblOrders[[#This Row],[Order Date]],"mmm-yyyy") -> Jan-2026 | R38: =IF(N38="Cancelled",0,H38*INDEX(Assumptions!$C$7:$C$12,MATCH(F38,Assumptions!$B$7:$B$12,0))) -> 748.699 | S38: =IF(N38="Cancelled",Assumptions!$C$19,IF(N38="Returned",Assumptions!$C$17+O38*Assumptions!$C$18+Assumptions!$C$20,Assumptions!$C$17+O38*Assumptions!$C$18)) -> 42.7 | T38: =R38+S38 -> 791.399 | U38: =K38-T38 -> 278.171 | V38: =IF(U38>0,U38,0) -> 278.171 | W38: =IF(U38>0,U38/H38,0) -> 0.26007741 | X38: =IF(U38<0,-U38,0) -> 0 | Y38: =IF(U38<0,-U38/H38,0) -> 0 | Z38: =IF(U38>=0,"Profitable",IF(N38="Cancelled","Order Cancelled",IF(N38="Returned","Order Returned",IF(AND(I38>=0.15,U38<0),"High Discount",IF(S38>H38,"Delivery Cost Exceeded Order Value","Low Order Value / Thin Margin"))))) -> Profitable
A39: ORD10204 | B39: 46053.697 | C39: Aryan Singh | D39: Delhi | E39: Mobile App | F39: Home & Living | G39: 5 | H39: 5892.2 | I39: 0.05 | J39: 0 | K39: =IF(N39="Cancelled",0,IF(N39="Returned",J39,H39*(1-I39)+J39)) -> 0 | L39: UPI/Wallet | M39: Jyoti Panda | N39: Cancelled | Q39: =TEXT(tblOrders[[#This Row],[Order Date]],"mmm-yyyy") -> Jan-2026 | R39: =IF(N39="Cancelled",0,H39*INDEX(Assumptions!$C$7:$C$12,MATCH(F39,Assumptions!$B$7:$B$12,0))) -> 0 | S39: =IF(N39="Cancelled",Assumptions!$C$19,IF(N39="Returned",Assumptions!$C$17+O39*Assumptions!$C$18+Assumptions!$C$20,Assumptions!$C$17+O39*Assumptions!$C$18)) -> 15 | T39: =R39+S39 -> 15 | U39: =K39-T39 -> -15 | V39: =IF(U39>0,U39,0) -> 0 | W39: =IF(U39>0,U39/H39,0) -> 0 | X39: =IF(U39<0,-U39,0) -> 15 | Y39: =IF(U39<0,-U39/H39,0) -> 0.0025457384 | Z39: =IF(U39>=0,"Profitable",IF(N39="Cancelled","Order Cancelled",IF(N39="Returned","Order Returned",IF(AND(I39>=0.15,U39<0),"High Discount",IF(S39>H39,"Delivery Cost Exceeded Order Value","Low Order Value / Thin Margin"))))) -> Order Cancelled
A40: ORD10126 | B40: 46055.392 | C40: Vivaan Verma | D40: Bhubaneswar | E40: Website | F40: Electronics | G40: 5 | H40: 14133.07 | I40: 0.2 | J40: 0 | K40: =IF(N40="Cancelled",0,IF(N40="Returned",J40,H40*(1-I40)+J40)) -> 11306.456 | L40: Credit/Debit Card | M40: Rekha Sethi | N40: Delivered | O40: 83 | P40: 4 | Q40: =TEXT(tblOrders[[#This Row],[Order Date]],"mmm-yyyy") -> Feb-2026 | R40: =IF(N40="Cancelled",0,H40*INDEX(Assumptions!$C$7:$C$12,MATCH(F40,Assumptions!$B$7:$B$12,0))) -> 12437.102 | S40: =IF(N40="Cancelled",Assumptions!$C$19,IF(N40="Returned",Assumptions!$C$17+O40*Assumptions!$C$18+Assumptions!$C$20,Assumptions!$C$17+O40*Assumptions!$C$18)) -> 49.9 | T40: =R40+S40 -> 12487.002 | U40: =K40-T40 -> -1180.5456 | V40: =IF(U40>0,U40,0) -> 0 | W40: =IF(U40>0,U40/H40,0) -> 0 | X40: =IF(U40<0,-U40,0) -> 1180.5456 | Y40: =IF(U40<0,-U40/H40,0) -> 0.083530726 | Z40: =IF(U40>=0,"Profitable",IF(N40="Cancelled","Order Cancelled",IF(N40="Returned","Order Returned",IF(AND(I40>=0.15,U40<0),"High Discount",IF(S40>H40,"Delivery Cost Exceeded Order Value","Low Order Value / Thin Margin"))))) -> High Discount
A41: ORD10212 | B41: 46056.494 | C41: Kritika Nair | D41: Pune | E41: Website | F41: Fashion | G41: 6 | H41: 610.95 | I41: 0.1 | J41: 49 | K41: =IF(N41="Cancelled",0,IF(N41="Returned",J41,H41*(1-I41)+J41)) -> 598.855 | L41: UPI/Wallet | M41: Omkar Naik | N41: Delivered | O41: 26 | P41: 3 | Q41: =TEXT(tblOrders[[#This Row],[Order Date]],"mmm-yyyy") -> Feb-2026 | R41: =IF(N41="Cancelled",0,H41*INDEX(Assumptions!$C$7:$C$12,MATCH(F41,Assumptions!$B$7:$B$12,0))) -> 336.0225 | S41: =IF(N41="Cancelled",Assumptions!$C$19,IF(N41="Returned",Assumptions!$C$17+O41*Assumptions!$C$18+Assumptions!$C$20,Assumptions!$C$17+O41*Assumptions!$C$18)) -> 32.8 | T41: =R41+S41 -> 368.8225 | U41: =K41-T41 -> 230.0325 | V41: =IF(U41>0,U41,0) -> 230.0325 | W41: =IF(U41>0,U41/H41,0) -> 0.37651608 | X41: =IF(U41<0,-U41,0) -> 0 | Y41: =IF(U41<0,-U41/H41,0) -> 0 | Z41: =IF(U41>=0,"Profitable",IF(N41="Cancelled","Order Cancelled",IF(N41="Returned","Order Returned",IF(AND(I41>=0.15,U41<0),"High Discount",IF(S41>H41,"Delivery Cost Exceeded Order Value","Low Order Value / Thin Margin"))))) -> Profitable
A42: ORD10122 | B42: 46056.849 | C42: Yash Ghosh | D42: Mumbai | E42: Mobile App | F42: Fashion | G42: 2 | H42: 2025.95 | I42: 0 | J42: 0 | K42: =IF(N42="Cancelled",0,IF(N42="Returned",J42,H42*(1-I42)+J42)) -> 2025.95 | L42: Net Banking | M42: Jyoti Panda | N42: Delivered | O42: 30 | P42: 3 | Q42: =TEXT(tblOrders[[#This Row],[Order Date]],"mmm-yyyy") -> Feb-2026 | R42: =IF(N42="Cancelled",0,H42*INDEX(Assumptions!$C$7:$C$12,MATCH(F42,Assumptions!$B$7:$B$12,0))) -> 1114.2725 | S42: =IF(N42="Cancelled",Assumptions!$C$19,IF(N42="Returned",Assumptions!$C$17+O42*Assumptions!$C$18+Assumptions!$C$20,Assumptions!$C$17+O42*Assumptions!$C$18)) -> 34 | T42: =R42+S42 -> 1148.2725 | U42: =K42-T42 -> 877.6775 | V42: =IF(U42>0,U42,0) -> 877.6775 | W42: =IF(U42>0,U42/H42,0) -> 0.43321775 | X42: =IF(U42<0,-U42,0) -> 0 | Y42: =IF(U42<0,-U42/H42,0) -> 0 | Z42: =IF(U42>=0,"Profitable",IF(N42="Cancelled","Order Cancelled",IF(N42="Returned","Order Returned",IF(AND(I42>=0.15,U42<0),"High Discount",IF(S42>H42,"Delivery Cost Exceeded Order Value","Low Order Value / Thin Margin"))))) -> Profitable
A43: ORD10186 | B43: 46057.868 | C43: Ananya Nair | D43: Chennai | E43: Mobile App | F43: Fashion | G43: 3 | H43: 3508.08 | I43: 0 | J43: 0 | K43: =IF(N43="Cancelled",0,IF(N43="Returned",J43,H43*(1-I43)+J43)) -> 3508.08 | L43: Credit/Debit Card | M43: Manoj Tiwari | N43: Delivered | O43: 59 | P43: 3 | Q43: =TEXT(tblOrders[[#This Row],[Order Date]],"mmm-yyyy") -> Feb-2026 | R43: =IF(N43="Cancelled",0,H43*INDEX(Assumptions!$C$7:$C$12,MATCH(F43,Assumptions!$B$7:$B$12,0))) -> 1929.444 | S43: =IF(N43="Cancelled",Assumptions!$C$19,IF(N43="Returned",Assumptions!$C$17+O43*Assumptions!$C$18+Assumptions!$C$20,Assumptions!$C$17+O43*Assumptions!$C$18)) -> 42.7 | T43: =R43+S43 -> 1972.144 | U43: =K43-T43 -> 1535.936 | V43: =IF(U43>0,U43,0) -> 1535.936 | W43: =IF(U43>0,U43/H43,0) -> 0.4378281 | X43: =IF(U43<0,-U43,0) -> 0 | Y43: =IF(U43<0,-U43/H43,0) -> 0 | Z43: =IF(U43>=0,"Profitable",IF(N43="Cancelled","Order Cancelled",IF(N43="Returned","Order Returned",IF(AND(I43>=0.15,U43<0),"High Discount",IF(S43>H43,"Delivery Cost Exceeded Order Value","Low Order Value / Thin Margin"))))) -> Profitable
A44: ORD10138 | B44: 46057.897 | C44: Kritika Singh | D44: Hyderabad | E44: Mobile App | F44: Fashion | G44: 1 | H44: 1523.53 | I44: 0.15 | J44: 0 | K44: =IF(N44="Cancelled",0,IF(N44="Returned",J44,H44*(1-I44)+J44)) -> 1295.0005 | L44: Net Banking | M44: Kunal Mehta | N44: Delivered | O44: 41 | P44: 3 | Q44: =TEXT(tblOrders[[#This Row],[Order Date]],"mmm-yyyy") -> Feb-2026 | R44: =IF(N44="Cancelled",0,H44*INDEX(Assumptions!$C$7:$C$12,MATCH(F44,Assumptions!$B$7:$B$12,0))) -> 837.9415 | S44: =IF(N44="Cancelled",Assumptions!$C$19,IF(N44="Returned",Assumptions!$C$17+O44*Assumptions!$C$18+Assumptions!$C$20,Assumptions!$C$17+O44*Assumptions!$C$18)) -> 37.3 | T44: =R44+S44 -> 875.2415 | U44: =K44-T44 -> 419.759 | V44: =IF(U44>0,U44,0) -> 419.759 | W44: =IF(U44>0,U44/H44,0) -> 0.27551738 | X44: =IF(U44<0,-U44,0) -> 0 | Y44: =IF(U44<0,-U44/H44,0) -> 0 | Z44: =IF(U44>=0,"Profitable",IF(N44="Cancelled","Order Cancelled",IF(N44="Returned","Order Returned",IF(AND(I44>=0.15,U44<0),"High Discount",IF(S44>H44,"Delivery Cost Exceeded Order Value","Low Order Value / Thin Margin"))))) -> Profitable
A45: ORD10195 | B45: 46058.47 | C45: Riya Joshi | D45: Hyderabad | E45: Mobile App | F45: Food & Beverage | G45: 5 | H45: 580.01 | I45: 0.1 | J45: 49 | K45: =IF(N45="Cancelled",0,IF(N45="Returned",J45,H45*(1-I45)+J45)) -> 571.009 | L45: UPI/Wallet | M45: Rekha Sethi | N45: Delivered | O45: 56 | P45: 3 | Q45: =TEXT(tblOrders[[#This Row],[Order Date]],"mmm-yyyy") -> Feb-2026 | R45: =IF(N45="Cancelled",0,H45*INDEX(Assumptions!$C$7:$C$12,MATCH(F45,Assumptions!$B$7:$B$12,0))) -> 261.0045 | S45: =IF(N45="Cancelled",Assumptions!$C$19,IF(N45="Returned",Assumptions!$C$17+O45*Assumptions!$C$18+Assumptions!$C$20,Assumptions!$C$17+O45*Assumptions!$C$18)) -> 41.8 | T45: =R45+S45 -> 302.8045 | U45: =K45-T45 -> 268.2045 | V45: =IF(U45>0,U45,0) -> 268.2045 | W45: =IF(U45>0,U45/H45,0) -> 0.46241358 | X45: =IF(U45<0,-U45,0) -> 0 | Y45: =IF(U45<0,-U45/H45,0) -> 0 | Z45: =IF(U45>=0,"Profitable",IF(N45="Cancelled","Order Cancelled",IF(N45="Returned","Order Returned",IF(AND(I45>=0.15,U45<0),"High Discount",IF(S45>H45,"Delivery Cost Exceeded Order Value","Low Order Value / Thin Margin"))))) -> Profitable
A46: ORD10215 | B46: 46058.592 | C46: Kritika Menon | D46: Delhi | E46: Website | F46: Food & Beverage | G46: 2 | H46: 604.6 | I46: 0.2 | J46: 29 | K46: =IF(N46="Cancelled",0,IF(N46="Returned",J46,H46*(1-I46)+J46)) -> 512.68 | L46: Net Banking | M46: Sunil Barik | N46: Delivered | O46: 63 | P46: 4 | Q46: =TEXT(tblOrders[[#This Row],[Order Date]],"mmm-yyyy") -> Feb-2026 | R46: =IF(N46="Cancelled",0,H46*INDEX(Assumptions!$C$7:$C$12,MATCH(F46,Assumptions!$B$7:$B$12,0))) -> 272.07 | S46: =IF(N46="Cancelled",Assumptions!$C$19,IF(N46="Returned",Assumptions!$C$17+O46*Assumptions!$C$18+Assumptions!$C$20,Assumptions!$C$17+O46*Assumptions!$C$18)) -> 43.9 | T46: =R46+S46 -> 315.97 | U46: =K46-T46 -> 196.71 | V46: =IF(U46>0,U46,0) -> 196.71 | W46: =IF(U46>0,U46/H46,0) -> 0.32535561 | X46: =IF(U46<0,-U46,0) -> 0 | Y46: =IF(U46<0,-U46/H46,0) -> 0 | Z46: =IF(U46>=0,"Profitable",IF(N46="Cancelled","Order Cancelled",IF(N46="Returned","Order Returned",IF(AND(I46>=0.15,U46<0),"High Discount",IF(S46>H46,"Delivery Cost Exceeded Order Value","Low Order Value / Thin Margin"))))) -> Profitable
A47: ORD10127 | B47: 46058.806 | C47: Meera Kapoor | D47: Chennai | E47: Mobile App | F47: Pharmacy | G47: 2 | H47: 940.89 | I47: 0.1 | J47: 39 | K47: =IF(N47="Cancelled",0,IF(N47="Returned",J47,H47*(1-I47)+J47)) -> 0 | L47: Cash on Delivery | M47: Kunal Mehta | N47: Cancelled | Q47: =TEXT(tblOrders[[#This Row],[Order Date]],"mmm-yyyy") -> Feb-2026 | R47: =IF(N47="Cancelled",0,H47*INDEX(Assumptions!$C$7:$C$12,MATCH(F47,Assumptions!$B$7:$B$12,0))) -> 0 | S47: =IF(N47="Cancelled",Assumptions!$C$19,IF(N47="Returned",Assumptions!$C$17+O47*Assumptions!$C$18+Assumptions!$C$20,Assumptions!$C$17+O47*Assumptions!$C$18)) -> 15 | T47: =R47+S47 -> 15 | U47: =K47-T47 -> -15 | V47: =IF(U47>0,U47,0) -> 0 | W47: =IF(U47>0,U47/H47,0) -> 0 | X47: =IF(U47<0,-U47,0) -> 15 | Y47: =IF(U47<0,-U47/H47,0) -> 0.015942352 | Z47: =IF(U47>=0,"Profitable",IF(N47="Cancelled","Order Cancelled",IF(N47="Returned","Order Returned",IF(AND(I47>=0.15,U47<0),"High Discount",IF(S47>H47,"Delivery Cost Exceeded Order Value","Low Order Value / Thin Margin"))))) -> Order Cancelled
A48: ORD10086 | B48: 46058.844 | C48: Varun Bose | D48: Pune | E48: Mobile App | F48: Electronics | G48: 4 | H48: 11407.6 | I48: 0 | J48: 0 | K48: =IF(N48="Cancelled",0,IF(N48="Returned",J48,H48*(1-I48)+J48)) -> 11407.6 | L48: Credit/Debit Card | M48: Sunil Barik | N48: Delivered | O48: 47 | P48: 5 | Q48: =TEXT(tblOrders[[#This Row],[Order Date]],"mmm-yyyy") -> Feb-2026 | R48: =IF(N48="Cancelled",0,H48*INDEX(Assumptions!$C$7:$C$12,MATCH(F48,Assumptions!$B$7:$B$12,0))) -> 10038.688 | S48: =IF(N48="Cancelled",Assumptions!$C$19,IF(N48="Returned",Assumptions!$C$17+O48*Assumptions!$C$18+Assumptions!$C$20,Assumptions!$C$17+O48*Assumptions!$C$18)) -> 39.1 | T48: =R48+S48 -> 10077.788 | U48: =K48-T48 -> 1329.812 | V48: =IF(U48>0,U48,0) -> 1329.812 | W48: =IF(U48>0,U48/H48,0) -> 0.11657246 | X48: =IF(U48<0,-U48,0) -> 0 | Y48: =IF(U48<0,-U48/H48,0) -> 0 | Z48: =IF(U48>=0,"Profitable",IF(N48="Cancelled","Order Cancelled",IF(N48="Returned","Order Returned",IF(AND(I48>=0.15,U48<0),"High Discount",IF(S48>H48,"Delivery Cost Exceeded Order Value","Low Order Value / Thin Margin"))))) -> Profitable
